<?xml version="1.0" encoding="utf-8"?>
<mujoco model="biped_wheeled_robot">
  <compiler angle="radian" meshdir="meshes/"/>
  <option gravity="0 0 -9.81" timestep="0.002"/>

  <asset>
    <mesh name="base_link" file="base_link.STL"/>
    <mesh name="hip_pitch_actuator" file="hip_pitch_actuator.STL"/>
    <mesh name="hip_pitch_link" file="hip_pitch_link.STL"/>
    <mesh name="knee_pitch_link" file="knee_pitch_link.STL"/>
    <mesh name="ankle_wheel_link" file="ankle_wheel_link.STL"/>
    <mesh name="knee_ternery_link" file="knee_ternery_link.STL"/>
    <mesh name="knee_b_rod_link" file="knee_b_rod_link.STL"/>
    <mesh name="knee_pitch_actuator" file="knee_pitch_actuator.STL"/>
    <mesh name="knee_crank_link" file="knee_crank_link.STL"/>
    <mesh name="knee_u_rod_link" file="knee_u_rod_link.STL"/>
  </asset>

  <worldbody>
    <geom name="floor" type="plane" pos="0 0 -0.25" size="10 10 0.1" rgba="0.5 0.5 0.5 1" friction="0.8 0.5 0.1"/>

    <body name="torso" pos="0 0 0.4">
      <freejoint name="root"/>
      <inertial pos="0 0 0" mass="5.0" diaginertia="0.1 0.1 0.1"/>
      <geom type="box" size="0.2 0.3 0.1" rgba="0.8 0.2 0.2 1" mass="5.0"/>

      <body name="r_base_link" pos="0 0.3 0.1" quat="0.707105 -0.707108 0 0">
        <inertial pos="-0.07 0 0.0709952" quat="0 0.707107 0 0.707107" mass="3.51005" diaginertia="0.0186503 0.0168976 0.00237397"/>
        <geom type="mesh" mesh="base_link"/>
        
        <body name="rhip_pitch_actuator" pos="0 0 -0.03945" quat="0.670822 0.670824 0.2236 0.223599">
          <inertial pos="-6.92884e-05 0.068232 7.41068e-06" quat="0.706478 0.0252882 0.025265 0.706831" mass="2.70656" diaginertia="0.00308089 0.00200266 0.00199536"/>
          <geom type="mesh" mesh="hip_pitch_actuator"/>
          <body name="rhip_pitch_link">
            <inertial pos="0.122288 0.00340485 -0.000591129" quat="0.498342 0.501653 0.501653 0.498342" mass="2.21436" diaginertia="0.020162 0.0197901 0.000745523"/>
            <joint name="rhip_pitch_joint" pos="0 0 0" axis="0 1 0" range="-0.6 0.9" armature="0.0149" frictionloss="0.3" damping="0.03"/>
            <geom type="mesh" mesh="hip_pitch_link"/>
            <body name="rknee_pitch_link" pos="0.375 0 0" quat="0.707105 0 0.707108 0">
              <inertial pos="0.148784 0.000713563 0.00217024" quat="0.501825 0.498959 0.496599 0.502595" mass="2.15352" diaginertia="0.0413684 0.0408434 0.000706617"/>
              <joint name="rknee_pitch_joint" pos="0 0 0" axis="0 1 0" range="-1.1 1.5"/>
              <geom type="mesh" mesh="knee_pitch_link"/>
              <body name="rankle_wheel_link" pos="0.39297 0 0.004716" quat="0.447225 -1.64265e-06 -0.894422 1.64265e-06">
                <inertial pos="-3.19801e-06 -0.0458553 -6.54249e-06" quat="0.377742 0.597818 0.597612 0.377869" mass="7.47242" diaginertia="0.0210808 0.0123658 0.0123656"/>
                <joint name="rankle_wheel_joint" pos="0 0 0" axis="0 1 0" frictionloss="1" damping="0.1"/>
                <geom type="mesh" mesh="ankle_wheel_link"/>
              </body>
            </body>
            <body name="rknee_ternery_link">
              <inertial pos="-0.0153169 0.00369448 0.0292857" quat="0.688575 -0.179464 -0.160542 0.68402" mass="0.300664" diaginertia="0.000428677 0.000274198 0.000158953"/>
              <joint name="rknee_ternery_joint" pos="0 0 0" axis="0 1 0" range="-3 1.16"/>
              <geom type="mesh" mesh="knee_ternery_link"/>
              <body name="rknee_b_rod_link" pos="-0.018545 0.015 0.098265">
                <inertial pos="0.188395 -0.00152232 0" quat="0 0.707107 0 0.707107" mass="0.410882" diaginertia="0.00197372 0.00196739 1.66426e-05"/>
                <joint name="rknee_b_rod_joint" pos="0 0 0" axis="0 1 0"/>
                <geom type="mesh" mesh="knee_b_rod_link"/>
              </body>
            </body>
          </body>
        </body>
        <body name="rknee_pitch_actuator" pos="-0.14 0 -0.03445" quat="0.332967 0.332968 -0.623806 -0.623804">
          <inertial pos="5.09633e-05 0.063232 4.75241e-05" quat="0.270579 0.653429 0.653098 0.270705" mass="2.70656" diaginertia="0.00308089 0.00200266 0.00199536"/>
          <geom type="mesh" mesh="knee_pitch_actuator"/>
          <body name="rknee_crank_link">
            <inertial pos="0.00821808 0.0140749 -7.49109e-05" quat="0.501458 0.501458 0.498537 0.498537" mass="0.578923" diaginertia="0.000360458 0.000268787 0.000136005"/>
            <joint name="rknee_crank_joint" pos="0 0 0" axis="0 1 0" armature="0.0149" frictionloss="0.3" damping="0.03"/>
            <geom type="mesh" mesh="knee_crank_link"/>
            <body name="rknee_u_rod_link" pos="0.075 0.01 0" quat="0.470869 -1.51092e-06 0.882203 -1.51092e-06">
              <inertial pos="0.07 -0.00152232 0" quat="0 0.707107 0 0.707107" mass="0.210882" diaginertia="0.00009372 0.00008739 1.66426e-05"/>
              <joint name="rknee_u_rod_joint" pos="0 0 0" axis="0 1 0"/>
              <geom type="mesh" mesh="knee_u_rod_link"/>
            </body>
          </body>
        </body>
      </body>


      <body name="l_base_link" pos="0 -0.3 0.1" quat="0.707105 -0.707108 0 0">
        <inertial pos="-0.07 0 0.0709952" quat="0 0.707107 0 0.707107" mass="3.51005" diaginertia="0.0186503 0.0168976 0.00237397"/>
        <geom type="mesh" mesh="base_link"/>
        
        <body name="lhip_pitch_actuator" pos="0 0 -0.03945" quat="0.670822 0.670824 0.2236 0.223599">
          <inertial pos="-6.92884e-05 0.068232 7.41068e-06" quat="0.706478 0.0252882 0.025265 0.706831" mass="2.70656" diaginertia="0.00308089 0.00200266 0.00199536"/>
          <geom type="mesh" mesh="hip_pitch_actuator"/>
          <body name="lhip_pitch_link">
            <inertial pos="0.122288 0.00340485 -0.000591129" quat="0.498342 0.501653 0.501653 0.498342" mass="2.21436" diaginertia="0.020162 0.0197901 0.000745523"/>
            <joint name="lhip_pitch_joint" pos="0 0 0" axis="0 1 0" range="-0.6 0.9" armature="0.0149" frictionloss="0.3" damping="0.03"/>
            <geom type="mesh" mesh="hip_pitch_link"/>
            <body name="lknee_pitch_link" pos="0.375 0 0" quat="0.707105 0 0.707108 0">
              <inertial pos="0.148784 0.000713563 0.00217024" quat="0.501825 0.498959 0.496599 0.502595" mass="2.15352" diaginertia="0.0413684 0.0408434 0.000706617"/>
              <joint name="lknee_pitch_joint" pos="0 0 0" axis="0 1 0" range="-1.1 1.5"/>
              <geom type="mesh" mesh="knee_pitch_link"/>
              <body name="lankle_wheel_link" pos="0.39297 0 0.004716" quat="0.447225 -1.64265e-06 -0.894422 1.64265e-06">
                <inertial pos="-3.19801e-06 -0.0458553 -6.54249e-06" quat="0.377742 0.597818 0.597612 0.377869" mass="7.47242" diaginertia="0.0210808 0.0123658 0.0123656"/>
                <joint name="lankle_wheel_joint" pos="0 0 0" axis="0 1 0" frictionloss="1" damping="0.1"/>
                <geom type="mesh" mesh="ankle_wheel_link"/>
              </body>
            </body>
            <body name="lknee_ternery_link">
              <inertial pos="-0.0153169 0.00369448 0.0292857" quat="0.688575 -0.179464 -0.160542 0.68402" mass="0.300664" diaginertia="0.000428677 0.000274198 0.000158953"/>
              <joint name="lknee_ternery_joint" pos="0 0 0" axis="0 1 0" range="-3 1.16"/>
              <geom type="mesh" mesh="knee_ternery_link"/>
              <body name="lknee_b_rod_link" pos="-0.018545 0.015 0.098265">
                <inertial pos="0.188395 -0.00152232 0" quat="0 0.707107 0 0.707107" mass="0.410882" diaginertia="0.00197372 0.00196739 1.66426e-05"/>
                <joint name="lknee_b_rod_joint" pos="0 0 0" axis="0 1 0"/>
                <geom type="mesh" mesh="knee_b_rod_link"/>
              </body>
            </body>
          </body>
        </body>
        <body name="lknee_pitch_actuator" pos="-0.14 0 -0.03445" quat="0.332967 0.332968 -0.623806 -0.623804">
          <inertial pos="5.09633e-05 0.063232 4.75241e-05" quat="0.270579 0.653429 0.653098 0.270705" mass="2.70656" diaginertia="0.00308089 0.00200266 0.00199536"/>
          <geom type="mesh" mesh="knee_pitch_actuator"/>
          <body name="lknee_crank_link">
            <inertial pos="0.00821808 0.0140749 -7.49109e-05" quat="0.501458 0.501458 0.498537 0.498537" mass="0.578923" diaginertia="0.000360458 0.000268787 0.000136005"/>
            <joint name="lknee_crank_joint" pos="0 0 0" axis="0 1 0" armature="0.0149" frictionloss="0.3" damping="0.03"/>
            <geom type="mesh" mesh="knee_crank_link"/>
            <body name="lknee_u_rod_link" pos="0.075 0.01 0" quat="0.470869 -1.51092e-06 0.882203 -1.51092e-06">
              <inertial pos="0.07 -0.00152232 0" quat="0 0.707107 0 0.707107" mass="0.210882" diaginertia="0.00009372 0.00008739 1.66426e-05"/>
              <joint name="lknee_u_rod_joint" pos="0 0 0" axis="0 1 0"/>
              <geom type="mesh" mesh="knee_u_rod_link"/>
            </body>
          </body>
        </body>
      </body>
      
    </body>
  </worldbody>

  <equality>
    <connect name="rknee_u_rod_constraint" body1="rknee_u_rod_link" body2="rknee_ternery_link" anchor="0.14 0 0" solref="0.02 1" solimp="0.9 0.95 0.001"/>
    <connect name="rknee_b_rod_constraint" body1="rknee_b_rod_link" body2="rknee_pitch_link" anchor="0.375 0 0" solref="0.02 1" solimp="0.9 0.95 0.001"/>
    <connect name="lknee_u_rod_constraint" body1="lknee_u_rod_link" body2="lknee_ternery_link" anchor="0.14 0 0" solref="0.02 1" solimp="0.9 0.95 0.001"/>
    <connect name="lknee_b_rod_constraint" body1="lknee_b_rod_link" body2="lknee_pitch_link" anchor="0.375 0 0" solref="0.02 1" solimp="0.9 0.95 0.001"/>
  </equality>
  
  <actuator>
    <position name="rhip_act" joint="rhip_pitch_joint" kp="100" kv="50" ctrlrange="-1 1"/>
    <position name="rknee_act" joint="rknee_crank_joint" kp="100" kv="50" ctrlrange="-0.5 2.1"/>
    <position name="lhip_act" joint="lhip_pitch_joint" kp="100" kv="50" ctrlrange="-1 1"/>
    <position name="lknee_act" joint="lknee_crank_joint" kp="100" kv="50" ctrlrange="-0.5 2.1"/>
  </actuator>

  <sensor>
    <jointpos name="rhip_pos" joint="rhip_pitch_joint"/>
    <jointpos name="rknee_pos" joint="rknee_crank_joint"/>
    <jointpos name="lhip_pos" joint="lhip_pitch_joint"/>
    <jointpos name="lknee_pos" joint="lknee_crank_joint"/>
    
    <jointvel name="rhip_vel" joint="rhip_pitch_joint"/>
    <jointvel name="rknee_vel" joint="rknee_crank_joint"/>
    <jointvel name="lhip_vel" joint="lhip_pitch_joint"/>
    <jointvel name="lknee_vel" joint="lknee_crank_joint"/>
    
    <framepos name="torso_pos" objtype="body" objname="torso"/>
    <framequat name="torso_quat" objtype="body" objname="torso"/>
    <framelinvel name="torso_linvel" objtype="body" objname="torso"/>
    <frameangvel name="torso_angvel" objtype="body" objname="torso"/>
    
  </sensor>
  
</mujoco>